[2025-03-17T05:03:38.717+0000] {local_task_job_runner.py:123} INFO - ::group::Pre task execution logs
[2025-03-17T05:03:38.749+0000] {taskinstance.py:2614} INFO - Dependencies all met for dep_context=non-requeueable deps ti=<TaskInstance: loblaw_etl_and_training.run_etl scheduled__2025-03-16T00:00:00+00:00 [queued]>
[2025-03-17T05:03:38.758+0000] {taskinstance.py:2614} INFO - Dependencies all met for dep_context=requeueable deps ti=<TaskInstance: loblaw_etl_and_training.run_etl scheduled__2025-03-16T00:00:00+00:00 [queued]>
[2025-03-17T05:03:38.759+0000] {taskinstance.py:2867} INFO - Starting attempt 1 of 2
[2025-03-17T05:03:38.779+0000] {taskinstance.py:2890} INFO - Executing <Task(PythonOperator): run_etl> on 2025-03-16 00:00:00+00:00
[2025-03-17T05:03:39.046+0000] {standard_task_runner.py:104} INFO - Running: ['***', 'tasks', 'run', 'loblaw_etl_and_training', 'run_etl', 'scheduled__2025-03-16T00:00:00+00:00', '--job-id', '7', '--raw', '--subdir', 'DAGS_FOLDER/Scripts/ml_training_dag.py', '--cfg-path', '/tmp/tmpiux5aiqz']
[2025-03-17T05:03:38.853+0000] {warnings.py:112} WARNING - /home/***/.local/lib/python3.12/site-packages/***/task/task_runner/standard_task_runner.py:70: DeprecationWarning: This process (pid=60) is multi-threaded, use of fork() may lead to deadlocks in the child.
  pid = os.fork()

[2025-03-17T05:03:39.118+0000] {standard_task_runner.py:105} INFO - Job 7: Subtask run_etl
[2025-03-17T05:03:39.125+0000] {standard_task_runner.py:72} INFO - Started process 85 to run task
[2025-03-17T05:03:39.881+0000] {warnings.py:112} WARNING - /home/***/.local/lib/python3.12/site-packages/***/settings.py:209: DeprecationWarning: The sql_alchemy_conn option in [core] has been moved to the sql_alchemy_conn option in [database] - the old setting has been used, but please update your config.
  SQL_ALCHEMY_CONN = conf.get("database", "SQL_ALCHEMY_CONN")

[2025-03-17T05:03:40.273+0000] {task_command.py:467} INFO - Running <TaskInstance: loblaw_etl_and_training.run_etl scheduled__2025-03-16T00:00:00+00:00 [running]> on host b4dde35c7dfd
[2025-03-17T05:03:40.276+0000] {warnings.py:112} WARNING - /home/***/.local/lib/python3.12/site-packages/***/settings.py:470: DeprecationWarning: The sql_alchemy_conn option in [core] has been moved to the sql_alchemy_conn option in [database] - the old setting has been used, but please update your config.
  if conf.get("database", "sql_alchemy_conn") == "none://":

[2025-03-17T05:03:40.670+0000] {taskinstance.py:3134} INFO - Exporting env vars: AIRFLOW_CTX_DAG_OWNER='***' AIRFLOW_CTX_DAG_ID='loblaw_etl_and_training' AIRFLOW_CTX_TASK_ID='run_etl' AIRFLOW_CTX_EXECUTION_DATE='2025-03-16T00:00:00+00:00' AIRFLOW_CTX_TRY_NUMBER='1' AIRFLOW_CTX_DAG_RUN_ID='scheduled__2025-03-16T00:00:00+00:00'
[2025-03-17T05:03:40.675+0000] {logging_mixin.py:190} INFO - Task instance is in running state
[2025-03-17T05:03:40.676+0000] {logging_mixin.py:190} INFO -  Previous state of the Task instance: queued
[2025-03-17T05:03:40.677+0000] {logging_mixin.py:190} INFO - Current task name:run_etl state:running start_date:2025-03-17 05:03:38.749808+00:00
[2025-03-17T05:03:40.679+0000] {logging_mixin.py:190} INFO - Dag name:loblaw_etl_and_training and current dag run status:running
[2025-03-17T05:03:40.680+0000] {taskinstance.py:732} INFO - ::endgroup::
[2025-03-17T05:03:40.682+0000] {etl_dag.py:61} INFO - Starting ETL process
[2025-03-17T05:03:40.684+0000] {etl_dag.py:65} ERROR - Error in ETL process: name 'run_etl_process' is not defined
[2025-03-17T05:03:40.688+0000] {taskinstance.py:3313} ERROR - Task failed with exception
Traceback (most recent call last):
  File "/home/airflow/.local/lib/python3.12/site-packages/airflow/models/taskinstance.py", line 768, in _execute_task
    result = _execute_callable(context=context, **execute_callable_kwargs)
             ^^^^^^^^^^^^^^^^^^^^^^^^^^^^^^^^^^^^^^^^^^^^^^^^^^^^^^^^^^^^^
  File "/home/airflow/.local/lib/python3.12/site-packages/airflow/models/taskinstance.py", line 734, in _execute_callable
    return ExecutionCallableRunner(
           ^^^^^^^^^^^^^^^^^^^^^^^^
  File "/home/airflow/.local/lib/python3.12/site-packages/airflow/utils/operator_helpers.py", line 252, in run
    return self.func(*args, **kwargs)
           ^^^^^^^^^^^^^^^^^^^^^^^^^^
  File "/home/airflow/.local/lib/python3.12/site-packages/airflow/models/baseoperator.py", line 424, in wrapper
    return func(self, *args, **kwargs)
           ^^^^^^^^^^^^^^^^^^^^^^^^^^^
  File "/home/airflow/.local/lib/python3.12/site-packages/airflow/operators/python.py", line 238, in execute
    return_value = self.execute_callable()
                   ^^^^^^^^^^^^^^^^^^^^^^^
  File "/home/airflow/.local/lib/python3.12/site-packages/airflow/operators/python.py", line 256, in execute_callable
    return runner.run(*self.op_args, **self.op_kwargs)
           ^^^^^^^^^^^^^^^^^^^^^^^^^^^^^^^^^^^^^^^^^^^
  File "/home/airflow/.local/lib/python3.12/site-packages/airflow/utils/operator_helpers.py", line 252, in run
    return self.func(*args, **kwargs)
           ^^^^^^^^^^^^^^^^^^^^^^^^^^
  File "/opt/airflow/dags/Scripts/etl_dag.py", line 62, in run_etl
    run_etl_process()  # Directly call 'run_etl_process'
    ^^^^^^^^^^^^^^^
NameError: name 'run_etl_process' is not defined
[2025-03-17T05:03:40.753+0000] {logging_mixin.py:190} INFO - Task instance in failure state
[2025-03-17T05:03:40.754+0000] {logging_mixin.py:190} INFO - Task start:2025-03-17 05:03:38.749808+00:00 end:2025-03-17 05:03:40.749455+00:00 duration:1.999647
[2025-03-17T05:03:40.755+0000] {logging_mixin.py:190} INFO - Task:<Task(PythonOperator): run_etl> dag:<DAG: loblaw_etl_and_training> dagrun:<DagRun loblaw_etl_and_training @ 2025-03-16 00:00:00+00:00: scheduled__2025-03-16T00:00:00+00:00, state:running, queued_at: 2025-03-17 05:03:19.578050+00:00. externally triggered: False>
[2025-03-17T05:03:40.756+0000] {logging_mixin.py:190} INFO - Failure caused by name 'run_etl_process' is not defined
[2025-03-17T05:03:40.756+0000] {taskinstance.py:1226} INFO - Marking task as UP_FOR_RETRY. dag_id=loblaw_etl_and_training, task_id=run_etl, run_id=scheduled__2025-03-16T00:00:00+00:00, execution_date=20250316T000000, start_date=20250317T050338, end_date=20250317T050340
[2025-03-17T05:03:40.832+0000] {taskinstance.py:341} INFO - ::group::Post task execution logs
[2025-03-17T05:03:40.833+0000] {standard_task_runner.py:124} ERROR - Failed to execute job 7 for task run_etl (name 'run_etl_process' is not defined; 85)
Traceback (most recent call last):
  File "/home/airflow/.local/lib/python3.12/site-packages/airflow/task/task_runner/standard_task_runner.py", line 117, in _start_by_fork
    ret = args.func(args, dag=self.dag)
          ^^^^^^^^^^^^^^^^^^^^^^^^^^^^^
  File "/home/airflow/.local/lib/python3.12/site-packages/airflow/cli/cli_config.py", line 49, in command
    return func(*args, **kwargs)
           ^^^^^^^^^^^^^^^^^^^^^
  File "/home/airflow/.local/lib/python3.12/site-packages/airflow/utils/cli.py", line 116, in wrapper
    return f(*args, **kwargs)
           ^^^^^^^^^^^^^^^^^^
  File "/home/airflow/.local/lib/python3.12/site-packages/airflow/cli/commands/task_command.py", line 483, in task_run
    task_return_code = _run_task_by_selected_method(args, _dag, ti)
                       ^^^^^^^^^^^^^^^^^^^^^^^^^^^^^^^^^^^^^^^^^^^^
  File "/home/airflow/.local/lib/python3.12/site-packages/airflow/cli/commands/task_command.py", line 256, in _run_task_by_selected_method
    return _run_raw_task(args, ti)
           ^^^^^^^^^^^^^^^^^^^^^^^
  File "/home/airflow/.local/lib/python3.12/site-packages/airflow/cli/commands/task_command.py", line 341, in _run_raw_task
    return ti._run_raw_task(
           ^^^^^^^^^^^^^^^^^
  File "/home/airflow/.local/lib/python3.12/site-packages/airflow/utils/session.py", line 97, in wrapper
    return func(*args, session=session, **kwargs)
           ^^^^^^^^^^^^^^^^^^^^^^^^^^^^^^^^^^^^^^
  File "/home/airflow/.local/lib/python3.12/site-packages/airflow/models/taskinstance.py", line 3006, in _run_raw_task
    return _run_raw_task(
           ^^^^^^^^^^^^^^
  File "/home/airflow/.local/lib/python3.12/site-packages/airflow/models/taskinstance.py", line 274, in _run_raw_task
    TaskInstance._execute_task_with_callbacks(
  File "/home/airflow/.local/lib/python3.12/site-packages/airflow/models/taskinstance.py", line 3161, in _execute_task_with_callbacks
    result = self._execute_task(context, task_orig)
             ^^^^^^^^^^^^^^^^^^^^^^^^^^^^^^^^^^^^^^
  File "/home/airflow/.local/lib/python3.12/site-packages/airflow/models/taskinstance.py", line 3185, in _execute_task
    return _execute_task(self, context, task_orig)
           ^^^^^^^^^^^^^^^^^^^^^^^^^^^^^^^^^^^^^^^
  File "/home/airflow/.local/lib/python3.12/site-packages/airflow/models/taskinstance.py", line 768, in _execute_task
    result = _execute_callable(context=context, **execute_callable_kwargs)
             ^^^^^^^^^^^^^^^^^^^^^^^^^^^^^^^^^^^^^^^^^^^^^^^^^^^^^^^^^^^^^
  File "/home/airflow/.local/lib/python3.12/site-packages/airflow/models/taskinstance.py", line 734, in _execute_callable
    return ExecutionCallableRunner(
           ^^^^^^^^^^^^^^^^^^^^^^^^
  File "/home/airflow/.local/lib/python3.12/site-packages/airflow/utils/operator_helpers.py", line 252, in run
    return self.func(*args, **kwargs)
           ^^^^^^^^^^^^^^^^^^^^^^^^^^
  File "/home/airflow/.local/lib/python3.12/site-packages/airflow/models/baseoperator.py", line 424, in wrapper
    return func(self, *args, **kwargs)
           ^^^^^^^^^^^^^^^^^^^^^^^^^^^
  File "/home/airflow/.local/lib/python3.12/site-packages/airflow/operators/python.py", line 238, in execute
    return_value = self.execute_callable()
                   ^^^^^^^^^^^^^^^^^^^^^^^
  File "/home/airflow/.local/lib/python3.12/site-packages/airflow/operators/python.py", line 256, in execute_callable
    return runner.run(*self.op_args, **self.op_kwargs)
           ^^^^^^^^^^^^^^^^^^^^^^^^^^^^^^^^^^^^^^^^^^^
  File "/home/airflow/.local/lib/python3.12/site-packages/airflow/utils/operator_helpers.py", line 252, in run
    return self.func(*args, **kwargs)
           ^^^^^^^^^^^^^^^^^^^^^^^^^^
  File "/opt/airflow/dags/Scripts/etl_dag.py", line 62, in run_etl
    run_etl_process()  # Directly call 'run_etl_process'
    ^^^^^^^^^^^^^^^
NameError: name 'run_etl_process' is not defined
[2025-03-17T05:03:40.913+0000] {local_task_job_runner.py:266} INFO - Task exited with return code 1
[2025-03-17T05:03:40.983+0000] {taskinstance.py:3901} INFO - 0 downstream tasks scheduled from follow-on schedule check
[2025-03-17T05:03:40.986+0000] {local_task_job_runner.py:245} INFO - ::endgroup::
